Workbook

Sheet Drink Costing
A1: TASTING FLIGHT COSTING
A3: 1. Mango Coconut Matcha
A4: Component | B4: Amount (g/ml) | C4: Cost/Unit (₱) | D4: Line Cost (₱) | E4: Notes
A5: Mango Concentrate | B5: 20 | C5: ='Ingredient Prices'!E13 -> 0.478 | D5: =B5*C5 -> 9.56 | E5: Raw ingredient
A6: Vita Coco | B6: 65 | C6: ='Ingredient Prices'!E8 -> 0.13 | D6: =B6*C6 -> 8.45 | E6: Raw ingredient
A7: Hot Whisked Matcha | B7: 22 | C7: ='Sub-Recipes'!D9 -> 1.4545909 | D7: =B7*C7 -> 32.001 | E7: Sub-recipe (see Sub-Recipes sheet)
A8: Cup | B8: 1 | C8: ='Ingredient Prices'!E18 -> 7.78 | D8: =B8*C8 -> 7.78 | E8: Raw ingredient
A9: INGREDIENT COST | D9: =SUM(D5:D8) -> 57.791
A11: 2. Earl Grey Coconut Latte
A12: Component | B12: Amount (g/ml) | C12: Cost/Unit (₱) | D12: Line Cost (₱) | E12: Notes
A13: Earl Grey Syrup | B13: 20 | C13: ='Sub-Recipes'!D75 -> 0.17309255 | D13: =B13*C13 -> 3.461851 | E13: Sub-recipe (see Sub-Recipes sheet)
A14: Vita Coco | B14: 65 | C14: ='Ingredient Prices'!E8 -> 0.13 | D14: =B14*C14 -> 8.45 | E14: Raw ingredient
A15: Cold Whisked Oat Matcha | B15: 22 | C15: ='Sub-Recipes'!D17 -> 1.5545455 | D15: =B15*C15 -> 34.2 | E15: Sub-recipe (see Sub-Recipes sheet)
A16: Cup | B16: 1 | C16: ='Ingredient Prices'!E18 -> 7.78 | D16: =B16*C16 -> 7.78 | E16: Raw ingredient
A17: INGREDIENT COST | D17: =SUM(D13:D16) -> 53.891851
A19: 3. Coco Pandan Cloud Matcha
A20: Component | B20: Amount (g/ml) | C20: Cost/Unit (₱) | D20: Line Cost (₱) | E20: Notes
A21: Vita Coco | B21: 65 | C21: ='Ingredient Prices'!E8 -> 0.13 | D21: =B21*C21 -> 8.45 | E21: Raw ingredient
A22: Sugar Syrup (1:1) | B22: 8 | C22: ='Sub-Recipes'!D66 -> 0.045025 | D22: =B22*C22 -> 0.3602 | E22: Sub-recipe (see Sub-Recipes sheet)
A23: Pandan Extract | B23: 0.1 | C23: ='Ingredient Prices'!E16 -> 5 | D23: =B23*C23 -> 0.5 | E23: Raw ingredient
A24: Pandan Leaf (garnish) | B24: 1 | C24: ='Ingredient Prices'!E17 -> 0.6 | D24: =B24*C24 -> 0.6 | E24: Raw ingredient
A25: Matcha Cream | B25: 27 | C25: ='Sub-Recipes'!D26 -> 1.5388889 | D25: =B25*C25 -> 41.55 | E25: Sub-recipe (see Sub-Recipes sheet)
A26: Cup | B26: 1 | C26: ='Ingredient Prices'!E18 -> 7.78 | D26: =B26*C26 -> 7.78 | E26: Raw ingredient
A27: INGREDIENT COST | D27: =SUM(D21:D26) -> 59.2402
A29: 4. Latik Foam Coconut Cold Brew
A30: Component | B30: Amount (g/ml) | C30: Cost/Unit (₱) | D30: Line Cost (₱) | E30: Notes
A31: Coconut Cold Brew Base | B31: 87 | C31: ='Sub-Recipes'!D34 -> 0.49482759 | D31: =B31*C31 -> 43.05 | E31: Sub-recipe (see Sub-Recipes sheet)
A32: Sugar Syrup (1:1) | B32: 8 | C32: ='Sub-Recipes'!D66 -> 0.045025 | D32: =B32*C32 -> 0.3602 | E32: Sub-recipe (see Sub-Recipes sheet)
A33: Latik Foam | B33: 60 | C33: ='Sub-Recipes'!D51 -> 0.24645833 | D33: =B33*C33 -> 14.7875 | E33: Sub-recipe (see Sub-Recipes sheet)
A34: Latik Bits (garnish) | B34: 5 | C34: ='Sub-Recipes'!D58 -> 0.7 | D34: =B34*C34 -> 3.5 | E34: Sub-recipe (see Sub-Recipes sheet)
A35: Cup | B35: 1 | C35: ='Ingredient Prices'!E18 -> 7.78 | D35: =B35*C35 -> 7.78 | E35: Raw ingredient
A36: INGREDIENT COST | D36: =SUM(D31:D35) -> 69.4777
A39: TASTING FLIGHT SUMMARY (all 4 drinks)
A40: Drink | B40: Ingredient Cost | E40: Notes
A41: 1. Mango Coconut Matcha | B41: =D9 -> 57.791
A42: 2. Earl Grey Coconut Latte | B42: =D17 -> 53.891851
A43: 3. Coco Pandan Cloud Matcha | B43: =D27 -> 59.2402
A44: 4. Latik Foam Coconut Cold Brew | B44: =D36 -> 69.4777
A45: 4-Cup Carrier (per flight) | B45: ='Ingredient Prices'!E19 -> 8 | E45: Packaging — 1 carrier per flight
A46: TOTAL FLIGHT COST (incl. packaging) | B46: =SUM(B41:B44)+B45 -> 248.40075
...

Sheet Ingredient Prices
A1: INGREDIENT PRICE LIST (Philippine SRP, 2026 — adjust as needed)
A3: Ingredient | B3: Pack Size | C3: Unit | D3: Pack Price (₱) | E3: Cost per Unit (₱) | F3: Source / Note
A4: Matcha Powder | B4: 100 | C4: g | D4: 1600 | E4: =D4/B4 -> 16 | F4: Actual: ₱1,600 per 100g
A5: Hot Water | B5: 1000 | C5: g | D5: 0.05 | E5: =D5/B5 -> 5e-05 | F5: Negligible — filtered water
A6: Oat Milk (Barista) | B6: 1000 | C6: g | D6: 110 | E6: =D6/B6 -> 0.11 | F6: Actual: ₱110/L
A7: Whipping Cream | B7: 1000 | C7: g | D7: 450 | E7: =D7/B7 -> 0.45 | F7: Actual: ₱450/L
A8: Vita Coco | B8: 1000 | C8: g | D8: 130 | E8: =D8/B8 -> 0.13 | F8: Vita Coco 1L ~₱119–140
A9: Coconut Milk | B9: 400 | C9: g | D9: 65 | E9: =D9/B9 -> 0.1625 | F9: Coco Mama Fresh Gata 400ml ~₱65
A10: Coconut Cream | B10: 400 | C10: g | D10: 70 | E10: =D10/B10 -> 0.175 | F10: Coco Mama / similar premium 1st press
A11: Dark Brown Sugar | B11: 1000 | C11: g | D11: 95 | E11: =D11/B11 -> 0.095 | F11: Supermarket brown sugar ~₱90–100/kg
A12: White Sugar (for syrup) | B12: 1000 | C12: g | D12: 90 | E12: =D12/B12 -> 0.09 | F12: Refined sugar ~₱88–103/kg
A13: Mango Concentrate | B13: 500 | C13: g | D13: 239 | E13: =D13/B13 -> 0.478 | F13: Actual: ₱239 per 500ml
A14: Peach Syrup | B14: 750 | C14: g | D14: 550 | E14: =D14/B14 -> 0.73333333 | F14: Torani Peach 750ml ~₱520–590
A15: Earl Grey Tea Bag | B15: 10 | C15: pc | D15: 170 | E15: =D15/B15 -> 17 | F15: Actual: ₱170 per box of 10 bags
... A19: 4-Cup Carrier | B19: 100 | C19: pc | D19: 800 | E19: =D19/B19 -> 8 | F19: Actual: ₱800 per 100 pcs
A22: LEGEND:
A23: Blue text = editable input (change to update all costings)
A24: Black text = formula (do not edit manually)

Sheet Sub-Recipes
A1: SUB-RECIPE COSTING (cost per gram of finished prep)
A3: Hot Whisked Matcha
A4: Ingredient | B4: Amount (g) | C4: Cost/Unit (₱) | D4: Line Cost (₱) | E4: Notes
A5: Matcha Powder | B5: 2 | C5: ='Ingredient Prices'!E4 -> 16 | D5: =B5*C5 -> 32
A6: Hot Water | B6: 20 | C6: ='Ingredient Prices'!E5 -> 5e-05 | D6: =B6*C6 -> 0.001
A7: Total Raw Cost | B7: =SUM(B5:B6) -> 22 | D7: =SUM(D5:D6) -> 32.001
A8: Effective Yield (g) | B8: =B7*1 -> 22 | C8: 100% yield
A9: Cost per gram (finished) | D9: =D7/B8 -> 1.4545909
A11: Cold Whisked Oat Matcha
A12: Ingredient | B12: Amount (g) | C12: Cost/Unit (₱) | D12: Line Cost (₱) | E12: Notes
A13: Matcha Powder | B13: 2 | C13: ='Ingredient Prices'!E4 -> 16 | D13: =B13*C13 -> 32
A14: Oat Milk (Barista) | B14: 20 | C14: ='Ingredient Prices'!E6 -> 0.11 | D14: =B14*C14 -> 2.2
A15: Total Raw Cost | B15: =SUM(B13:B14) -> 22 | D15: =SUM(D13:D14) -> 34.2
A16: Effective Yield (g) | B16: =B15*1 -> 22 | C16: 100% yield
A17: Cost per gram (finished) | D17: =D15/B16 -> 1.5545455
A19: Matcha Cream
A20: Ingredient | B20: Amount (g) | C20: Cost/Unit (₱) | D20: Line Cost (₱) | E20: Notes
A21: Matcha Powder | B21: 2 | C21: ='Ingredient Prices'!E4 -> 16 | D21: =B21*C21 -> 32
A22: Whipping Cream | B22: 20 | C22: ='Ingredient Prices'!E7 -> 0.45 | D22: =B22*C22 -> 9
A23: Oat Milk (Barista) | B23: 5 | C23: ='Ingredient Prices'!E6 -> 0.11 | D23: =B23*C23 -> 0.55
A24: Total Raw Cost | B24: =SUM(B21:B23) -> 27 | D24: =SUM(D21:D23) -> 41.55
A25: Effective Yield (g) | B25: =B24*1 -> 27 | C25: 100% yield
A26: Cost per gram (finished) | D26: =D24/B25 -> 1.5388889
A28: Coconut Cold Brew Base
A29: Ingredient | B29: Amount (g) | C29: Cost/Unit (₱) | D29: Line Cost (₱) | E29: Notes
A30: Matcha Powder | B30: 2 | C30: ='Ingredient Prices'!E4 -> 16 | D30: =B30*C30 -> 32
A31: Vita Coco | B31: 85 | C31: ='Ingredient Prices'!E8 -> 0.13 | D31: =B31*C31 -> 11.05
A32: Total Raw Cost | B32: =SUM(B30:B31) -> 87 | D32: =SUM(D30:D31) -> 43.05
A33: Effective Yield (g) | B33: =B32*1 -> 87 | C33: 100% yield | E33: Batch in pitcher: 65g Vita Coco base + 20g Vita Coco whisked with 2g matcha, all combined
A34: Cost per gram (finished) | D34: =D32/B33 -> 0.49482759
A36: Latik Caramel
A37: Ingredient | B37: Amount (g) | C37: Cost/Unit (₱) | D37: Line Cost (₱) | E37: Notes
A38: Coconut Milk | B38: 200 | C38: ='Ingredient Prices'!E9 -> 0.1625 | D38: =B38*C38 -> 32.5
A39: Dark Brown Sugar | B39: 100 | C39: ='Ingredient Prices'!E11 -> 0.095 | D39: =B39*C39 -> 9.5
A40: Total Raw Cost | B40: =SUM(B38:B39) -> 300 | D40: =SUM(D38:D39) -> 42
A41: Effective Yield (g) | B41: =B40*0.75 -> 225 | C41: 75% yield | E41: Cooks down — yield estimated ~75% of input weight
A42: Cost per gram (finished) | D42: =D40/B41 -> 0.18666667
A44: Latik Foam
A45: Ingredient | B45: Amount (g) | C45: Cost/Unit (₱) | D45: Line Cost (₱) | E45: Notes
A46: Whipping Cream | B46: 60 | C46: ='Ingredient Prices'!E7 -> 0.45 | D46: =B46*C46 -> 27
...

Sheet Daily Prep
A1: DAILY PREP QUANTITIES
A3: Daily flight target: | B3: 150 | C3: flights | E3: ← Edit BLUE cells to change targets; all quantities auto-update
A4: Buffer %: | B4: 0.1 | C4: (spills, remakes, walk-up extras)
A5: Effective batch target: | B5: =B3*(1+B4) -> 165 | C5: (daily target × (1 + buffer))
A7: SECTION 1 — RAW INGREDIENTS (poured directly into drinks)
A8: Ingredient | B8: Per Flight | C8: Unit | D8: Total Needed | E8: Pack Size | F8: # Packs to Buy
A9: Mango Concentrate | B9: 20 | C9: g | D9: =B9*$B$5 -> 3300 | E9: 500 ml bottles | F9: =ROUNDUP(D9/500,0) -> 7
A10: Vita Coco (drinks 1+2+3 direct pour) | B10: 195 | C10: g | D10: =B10*$B$5 -> 32175 | E10: 1000 L cartons | F10: =ROUNDUP(D10/1000,0) -> 33
A11: Pandan Extract | B11: 0.1 | C11: ml | D11: =B11*$B$5 -> 16.5 | E11: 20 ml bottles | F11: =ROUNDUP(D11/20,0) -> 1
A12: Pandan Leaf | B12: 1 | C12: pc | D12: =B12*$B$5 -> 165 | E12: 25 leaves/bunch | F12: =ROUNDUP(D12/25,0) -> 7
A13: Cup | B13: 4 | C13: pc | D13: =B13*$B$5 -> 660 | E13: 50 pcs/sleeve | F13: =ROUNDUP(D13/50,0) -> 14
A14: 4-Cup Carrier | B14: 1 | C14: pc | D14: =B14*$B$5 -> 165 | E14: 100 pcs/pack | F14: =ROUNDUP(D14/100,0) -> 2
A16: SECTION 2 — SUB-RECIPES TO PRE-BATCH (made at commissary)
A17: Sub-Recipe | B17: Per Flight (finished) | C17: Unit | D17: Total Finished Needed | E17: Storage Container | F17: # Containers
A18: Earl Grey Syrup | B18: 20 | C18: g | D18: =B18*$B$5 -> 3300 | E18: 1L squeeze bottles | F18: =ROUNDUP(D18/1000,0) -> 4
A19: Sugar Syrup (1:1) | B19: 16 | C19: g | D19: =B19*$B$5 -> 2640 | E19: 1L squeeze bottles | F19: =ROUNDUP(D19/1000,0) -> 3
A20: Coconut Cold Brew Base | B20: 87 | C20: g | D20: =B20*$B$5 -> 14355 | E20: 2L pitchers (label: stir before pouring) | F20: =ROUNDUP(D20/2000,0) -> 8
A21: Matcha Cream (unfrothed base) | B21: 27 | C21: g | D21: =B21*$B$5 -> 4455 | E21: 2L pitchers (label: shake before frothing) | F21: =ROUNDUP(D21/2000,0) -> 3
A22: Latik Foam (unwhipped base, charge at booth) | B22: 60 | C22: g | D22: =B22*$B$5 -> 9900 | E22: 2L bottles for whip dispenser | F22: =ROUNDUP(D22/2000,0) -> 5
A23: Latik Caramel | B23: 30 | C23: g | D23: =B23*$B$5 -> 4950 | E23: 500ml squeeze bottles | F23: =ROUNDUP(D23/500,0) -> 10
A24: Latik Bits (5g pre-portions) | B24: 5 | C24: g | D24: =B24*$B$5 -> 825 | E24: 5g souffle cups, lidded | F24: =ROUNDUP(D24/5,0) -> 165
A25: Hot Matcha 12g bowl portions (drink 1) | B25: 2 | C25: g | D25: =B25*$B$5 -> 330 | E25: 12g zip bags (1 bag = 6 drinks) | F25: =ROUNDUP(D25/12,0) -> 28
A26: Cold Oat Matcha 12g bowl portions (drink 2) | B26: 2 | C26: g | D26: =B26*$B$5 -> 330 | E26: 12g zip bags (1 bag = 6 drinks) | F26: =ROUNDUP(D26/12,0) -> 28
A28: SECTION 3 — RAW INPUTS NEEDED FOR SUB-RECIPES (shopping list)
A29: Raw Ingredient | B29: Used In | C29: Per Flight (input) | D29: Unit | E29: Total Needed | F29: # Packs to Buy
A30: Matcha Powder | B30: Drinks 1,2,3,4 (whisks + creams + cold brew) | C30: 8 | D30: g | E30: =C30*$B$5 -> 1320 | F30: =ROUNDUP(E30/100,0)&" × 100g pack" -> 14 × 100g pack
A31: Vita Coco | B31: Drinks 1,2,3 direct + Coconut Cold Brew Base | C31: 280 | D31: g | E31: =C31*$B$5 -> 46200 | F31: =ROUNDUP(E31/1000,0)&" × 1L carton" -> 47 × 1L carton
A32: Hot Water (for matcha whisk) | B32: Hot Whisked Matcha (drink 1) | C32: 20 | D32: g | E32: =C32*$B$5 -> 3300 | F32: =ROUNDUP(E32/1000,0)&" × L (use kettle)" -> 4 × L (use kettle)
A33: Oat Milk (Barista) | B33: Cold Whisked Oat Matcha + Matcha Cream | C33: 25 | D33: g | E33: =C33*$B$5 -> 4125 | F33: =ROUNDUP(E33/1000,0)&" × 1L carton" -> 5 × 1L carton
A34: Whipping Cream | B34: Matcha Cream + Latik Foam | C34: 35 | D34: g | E34: =C34*$B$5 -> 5775 | F34: =ROUNDUP(E34/1000,0)&" × 1L carton" -> 6 × 1L carton
A35: Coconut Milk | B35: Latik Caramel + Latik Foam direct | C35: 41.67 | D35: g | E35: =C35*$B$5 -> 6875.55 | F35: =ROUNDUP(E35/400,0)&" × 400ml can" -> 18 × 400ml can
A36: Coconut Cream | B36: Latik Bits (garnish) | C36: 20 | D36: g | E36: =C36*$B$5 -> 3300 | F36: =ROUNDUP(E36/400,0)&" × 400ml can" -> 9 × 400ml can
A37: Dark Brown Sugar | B37: Latik Caramel | C37: 13.33 | D37: g | E37: =C37*$B$5 -> 2199.45 | F37: =ROUNDUP(E37/1000,0)&" × 1kg pack" -> 3 × 1kg pack
A38: White Sugar | B38: Sugar Syrup + Earl Grey Syrup | C38: 18.04 | D38: g | E38: =C38*$B$5 -> 2976.6 | F38: =ROUNDUP(E38/1000,0)&" × 1kg pack" -> 3 × 1kg pack
A39: Earl Grey Tea Bag | B39: Earl Grey Syrup | C39: 0.151 | D39: pc | E39: =C39*$B$5 -> 24.915 | F39: =ROUNDUP(E39/10,0)&" × 10-bag box" -> 3 × 10-bag box
A40: Water (for syrups) | B40: Sugar Syrup + Earl Grey Syrup | C40: 20.04 | D40: g | E40: =C40*$B$5 -> 3306.6 | F40: =ROUNDUP(E40/1000,0)&" × L (use kettle)" -> 4 × L (use kettle)
A42: SECTION 4 — # OF SUB-RECIPE BATCHES TO COOK (kitchen production list)
A43: Sub-Recipe | B43: 1 Batch Yields | C43: Per Flight Need | D43: Total Need | E43: Batches to Cook | F43: Recipe Notes
A44: Earl Grey Syrup | B44: 398.7 g | C44: 20 g | D44: =20*$B$5 -> 3300 | E44: =ROUNDUP(D44/398.7,0) -> 9 | F44: 240g water + 200g sugar + 3 tea bags → simmer/steep → cool (90% yield)
A45: Sugar Syrup (1:1) | B45: 200 g | C45: 16 g | D45: =16*$B$5 -> 2640 | E45: =ROUNDUP(D45/200,0) -> 14 | F45: 100g sugar + 100g hot water → dissolve fully → cool
...
