Workbook

Sheet Dashboard
A1: Matchanese MOA — Investor Lead Dashboard
A2: Generated May 08, 2026 · 121 qualified leads from Meta ad campaign
A4: Total Leads | C4: 🔥 Hot (Call Today) | E4: ⭐ Warm | G4: ₱3M+ Leads | I4: F&B Owners | K4: Avg Score
A5: =COUNTA('All Leads Ranked'!B2:B122) -> 121 | C5: =COUNTIF('All Leads Ranked'!P2:P122,"*HOT*") -> 11 | E5: =COUNTIF('All Leads Ranked'!P2:P122,"*Warm*") -> 31 | G5: =COUNTIF('All Leads Ranked'!H2:H122,"*3,000,000+*") -> 8 | I5: =COUNTIF('All Leads Ranked'!F2:F122,"Business owner (F&B)") -> 25 | K5: =ROUND(AVERAGE('All Leads Ranked'!N2:N122),0) -> 57
A9: Breakdowns
A11: Priority Tier | B11: Count | C11: % of Total | E11: Investment Range | F11: Count | G11: % of Total | I11: Profile Type | J11: Count | K11: % of Total
A12: 🔥 HOT — Call Today | B12: =COUNTIF('All Leads Ranked'!P2:P122,"🔥 HOT — Call Today") -> 11 | C12: =B12/121 -> 0.090909091 | E12: ₱3,000,000+ | F12: =COUNTIF('All Leads Ranked'!H2:H122,"*3,000,000+*") -> 8 | G12: =F12/121 -> 0.066115702 | I12: Business owner (F&B) | J12: =COUNTIF('All Leads Ranked'!F2:F122,"Business owner (F&B)") -> 25 | K12: =J12/121 -> 0.20661157
A13: ⭐ Warm — Call This Week | B13: =COUNTIF('All Leads Ranked'!P2:P122,"⭐ Warm — Call This Week") -> 31 | C13: =B13/121 -> 0.25619835 | E13: ₱1,000,000 – ₱3,000,000 | F13: =COUNTIF('All Leads Ranked'!H2:H122,"*1,000,000*3,000,000*") -> 19 | G13: =F13/121 -> 0.15702479 | I13: Business owner (Non-F&B) | J13: =COUNTIF('All Leads Ranked'!F2:F122,"Business owner (Non-F&B)") -> 20 | K13: =J13/121 -> 0.16528926
A14: 📋 Qualified — Email First | B14: =COUNTIF('All Leads Ranked'!P2:P122,"📋 Qualified — Email First") -> 79 | C14: =B14/121 -> 0.65289256 | E14: ₱500,000 – ₱1,000,000 | F14: =COUNTIF('All Leads Ranked'!H2:H122,"*500,000*1,000,000*") -> 94 | G14: =F14/121 -> 0.7768595 | I14: Investor | J14: =COUNTIF('All Leads Ranked'!F2:F122,"Investor") -> 40 | K14: =J14/121 -> 0.33057851
A15: ❄️ Low — Nurture | B15: =COUNTIF('All Leads Ranked'!P2:P122,"❄️ Low — Nurture") -> 0 | C15: =B15/121 -> 0 | I15: Planning to start | J15: =COUNTIF('All Leads Ranked'!F2:F122,"Planning to start a business") -> 36 | K15: =J15/121 -> 0.29752066
A16: TOTAL | B16: =SUM(B12:B15) -> 121 | C16: =SUM(C12:C15) -> 1
A19: 🚨 Top 15 — Call These FIRST
A20: Rank | B20: Name | C20: Phone | D20: Email | E20: Investment | F20: Profile | G20: Involvement | H20: Score | I20: Why
A21: 1 | B21: Jenny So | C21: +639175790579 | D21: Jtsohu@gmail.com | E21: ₱3,000,000+ | F21: Business owner (F&B) | G21: Both (operator + investor) | H21: 95 | I21: ₱3M+ budget · wants both roles · F&B owner
A22: 2 | B22: Ernest Vergel de Dios | C22: +639992264246 | D22: erlvdd@gmail.com | E22: ₱3,000,000+ | F22: Business owner (F&B) | G22: Both (operator + investor) | H22: 95 | I22: ₱3M+ budget · wants both roles · F&B owner
A23: 3 | B23: daynard tan | C23: +639189080848 | D23: daynardtan@pancocafe.com | E23: ₱3,000,000+ | F23: Business owner (F&B) | G23: Both (operator + investor) | H23: 95 | I23: ₱3M+ budget · wants both roles · F&B owner
A24: 4 | B24: Harry | C24: +17787983016 | D24: Harp57@protonmail.com | E24: ₱3,000,000+ | F24: Business owner (F&B) | G24: Both (operator + investor) | H24: 95 | I24: ₱3M+ budget · wants both roles · F&B owner
A25: 5 | B25: Gen Antonio | D25: geninem.antonio@gmail.com | E25: ₱3,000,000+ | F25: Business owner (F&B) | G25: Both (operator + investor) | H25: 95 | I25: ₱3M+ budget · wants both roles · F&B owner
A26: 6 | B26: Jane Asis | C26: +639279433186 | D26: janedepalco@yahoo.com.ph | E26: ₱3,000,000+ | F26: Business owner (F&B) | G26: Active operator (hands-on) | H26: 90 | I26: ₱3M+ budget · hands-on operator · F&B owner
A27: 7 | B27: Sofia Kamille Tagle | C27: +639686500117 | D27: sofiakamille888@gmail.com | E27: ₱3,000,000+ | F27: Investor | G27: Both (operator + investor) | H27: 87 | I27: ₱3M+ budget · wants both roles · investor profile
A28: 8 | B28: Millie de Luna-Daluz | C28: +639178650824 | D28: millie@aluyan.ph | E28: ₱3,000,000+ | F28: Business owner (Non-F&B) | G28: Active operator (hands-on) | H28: 85 | I28: ₱3M+ budget · hands-on operator · non-F&B owner
A29: 9 | B29: Mark Lopez | C29: +639178776275 | D29: lopezmarkkelvin@gmail.com | E29: ₱1,000,000 – ₱3,000,000 | F29: Business owner (F&B) | G29: Both (operator + investor) | H29: 80 | I29: ₱1-3M budget · wants both roles · F&B owner
A30: 10 | B30: Tish Darroca | C30: +639778069760 | D30: darroca.patricia@gmail.com | E30: ₱1,000,000 – ₱3,000,000 | F30: Business owner (F&B) | G30: Both (operator + investor) | H30: 80 | I30: ₱1-3M budget · wants both roles · F&B owner
A31: 11 | B31: Charles Lee | C31: +639155304159 | D31: charles.james.lee99@gmail.com | E31: ₱1,000,000 – ₱3,000,000 | F31: Business owner (F&B) | G31: Both (operator + investor) | H31: 80 | I31: ₱1-3M budget · wants both roles · F&B owner
A32: 12 | B32: Clare Alvarez | C32: +639175988269 | D32: clare.alvarez@guildsec.com | E32: ₱1,000,000 – ₱3,000,000 | F32: Business owner (F&B) | G32: Active operator (hands-on) | H32: 75 | I32: ₱1-3M budget · hands-on operator · F&B owner
A33: 13 | B33: Sheery He | C33: +639177188658 | D33: sheeryhe.ogci@yahoo.com | E33: ₱1,000,000 – ₱3,000,000 | F33: Business owner (Non-F&B) | G33: Both (operator + investor) | H33: 75 | I33: ₱1-3M budget · wants both roles · non-F&B owner
A34: 14 | B34: Patricia Darroca | C34: +639778069760 | D34: darroca.patricia@gmail.com | E34: ₱1,000,000 – ₱3,000,000 | F34: Business owner (Non-F&B) | G34: Both (operator + investor) | H34: 75 | I34: ₱1-3M budget · wants both roles · non-F&B owner
A35: 15 | B35: RV Navia | D35: unessima@gmail.com | E35: ₱1,000,000 – ₱3,000,000 | F35: Investor | G35: Both (operator + investor) | H35: 72 | I35: ₱1-3M budget · wants both roles · investor profile

Sheet Hot Leads
A1: 🔥 Hot Leads — Call Today
A2: Score ≥ 80. Pitch the full deck, push for soonest meeting.
A4: Rank | B4: Name | C4: Phone | D4: Email | E4: Investment | F4: Profile | G4: Involvement | H4: Score | I4: Why | J4: Suggested Action
A5: 1 | B5: Jenny So | C5: +639175790579 | D5: Jtsohu@gmail.com | E5: ₱3,000,000+ | F5: Business owner (F&B) | G5: Both (operator + investor) | H5: 95 | I5: ₱3M+ budget · wants both roles · F&B owner | J5: Call within 24hr; pitch full deck
A6: 2 | B6: Ernest Vergel de Dios | C6: +639992264246 | D6: erlvdd@gmail.com | E6: ₱3,000,000+ | F6: Business owner (F&B) | G6: Both (operator + investor) | H6: 95 | I6: ₱3M+ budget · wants both roles · F&B owner | J6: Call within 24hr; pitch full deck
A7: 3 | B7: daynard tan | C7: +639189080848 | D7: daynardtan@pancocafe.com | E7: ₱3,000,000+ | F7: Business owner (F&B) | G7: Both (operator + investor) | H7: 95 | I7: ₱3M+ budget · wants both roles · F&B owner | J7: Call within 24hr; pitch full deck
A8: 4 | B8: Harry | C8: +17787983016 | D8: Harp57@protonmail.com | E8: ₱3,000,000+ | F8: Business owner (F&B) | G8: Both (operator + investor) | H8: 95 | I8: ₱3M+ budget · wants both roles · F&B owner | J8: Call within 24hr; pitch full deck
A9: 5 | B9: Gen Antonio | D9: geninem.antonio@gmail.com | E9: ₱3,000,000+ | F9: Business owner (F&B) | G9: Both (operator + investor) | H9: 95 | I9: ₱3M+ budget · wants both roles · F&B owner | J9: Call within 24hr; pitch full deck
A10: 6 | B10: Jane Asis | C10: +639279433186 | D10: janedepalco@yahoo.com.ph | E10: ₱3,000,000+ | F10: Business owner (F&B) | G10: Active operator (hands-on) | H10: 90 | I10: ₱3M+ budget · hands-on operator · F&B owner | J10: Call within 24hr; pitch full deck
A11: 7 | B11: Sofia Kamille Tagle | C11: +639686500117 | D11: sofiakamille888@gmail.com | E11: ₱3,000,000+ | F11: Investor | G11: Both (operator + investor) | H11: 87 | I11: ₱3M+ budget · wants both roles · investor profile | J11: Call within 24hr; pitch full deck
A12: 8 | B12: Millie de Luna-Daluz | C12: +639178650824 | D12: millie@aluyan.ph | E12: ₱3,000,000+ | F12: Business owner (Non-F&B) | G12: Active operator (hands-on) | H12: 85 | I12: ₱3M+ budget · hands-on operator · non-F&B owner | J12: Call within 24hr; pitch full deck
A13: 9 | B13: Mark Lopez | C13: +639178776275 | D13: lopezmarkkelvin@gmail.com | E13: ₱1,000,000 – ₱3,000,000 | F13: Business owner (F&B) | G13: Both (operator + investor) | H13: 80 | I13: ₱1-3M budget · wants both roles · F&B owner | J13: Call within 24hr; pitch full deck
A14: 10 | B14: Tish Darroca | C14: +639778069760 | D14: darroca.patricia@gmail.com | E14: ₱1,000,000 – ₱3,000,000 | F14: Business owner (F&B) | G14: Both (operator + investor) | H14: 80 | I14: ₱1-3M budget · wants both roles · F&B owner | J14: Call within 24hr; pitch full deck
A15: 11 | B15: Charles Lee | C15: +639155304159 | D15: charles.james.lee99@gmail.com | E15: ₱1,000,000 – ₱3,000,000 | F15: Business owner (F&B) | G15: Both (operator + investor) | H15: 80 | I15: ₱1-3M budget · wants both roles · F&B owner | J15: Call within 24hr; pitch full deck

Sheet All Leads Ranked
A1: Rank | B1: Name | C1: Phone | D1: Email | E1: Submitted | F1: Profile | G1: Involvement | H1: Investment | I1: Profile pts | J1: Involvement pts | K1: Investment pts | L1: Recency pts | N1: TOTAL SCORE | O1: Why this score | P1: Priority Tier | Q1: Suggested Action
A2: 1 | B2: Jenny So | C2: +639175790579 | D2: Jtsohu@gmail.com | E2: 2026-04-28 00:12 | F2: Business owner (F&B) | G2: Both (operator + investor) | H2: ₱3,000,000+ | I2: 20 | J2: 30 | K2: 40 | L2: 5 | N2: =I2+J2+K2+L2 -> 95 | O2: ₱3M+ budget · wants both roles · F&B owner | P2: 🔥 HOT — Call Today | Q2: Call within 24hr; pitch full deck
A3: 2 | B3: Ernest Vergel de Dios | C3: +639992264246 | D3: erlvdd@gmail.com | E3: 2026-04-26 13:31 | F3: Business owner (F&B) | G3: Both (operator + investor) | H3: ₱3,000,000+ | I3: 20 | J3: 30 | K3: 40 | L3: 5 | N3: =I3+J3+K3+L3 -> 95 | O3: ₱3M+ budget · wants both roles · F&B owner | P3: 🔥 HOT — Call Today | Q3: Call within 24hr; pitch full deck
A4: 3 | B4: daynard tan | C4: +639189080848 | D4: daynardtan@pancocafe.com | E4: 2026-04-26 03:23 | F4: Business owner (F&B) | G4: Both (operator + investor) | H4: ₱3,000,000+ | I4: 20 | J4: 30 | K4: 40 | L4: 5 | N4: =I4+J4+K4+L4 -> 95 | O4: ₱3M+ budget · wants both roles · F&B owner | P4: 🔥 HOT — Call Today | Q4: Call within 24hr; pitch full deck
A5: 4 | B5: Harry | C5: +17787983016 | D5: Harp57@protonmail.com | E5: 2026-04-25 12:12 | F5: Business owner (F&B) | G5: Both (operator + investor) | H5: ₱3,000,000+ | I5: 20 | J5: 30 | K5: 40 | L5: 5 | N5: =I5+J5+K5+L5 -> 95 | O5: ₱3M+ budget · wants both roles · F&B owner | P5: 🔥 HOT — Call Today | Q5: Call within 24hr; pitch full deck
A6: 5 | B6: Gen Antonio | D6: geninem.antonio@gmail.com | E6: 2026-04-24 07:26 | F6: Business owner (F&B) | G6: Both (operator + investor) | H6: ₱3,000,000+ | I6: 20 | J6: 30 | K6: 40 | L6: 5 | N6: =I6+J6+K6+L6 -> 95 | O6: ₱3M+ budget · wants both roles · F&B owner | P6: 🔥 HOT — Call Today | Q6: Call within 24hr; pitch full deck
A7: 6 | B7: Jane Asis | C7: +639279433186 | D7: janedepalco@yahoo.com.ph | E7: 2026-04-26 01:37 | F7: Business owner (F&B) | G7: Active operator (hands-on) | H7: ₱3,000,000+ | I7: 20 | J7: 25 | K7: 40 | L7: 5 | N7: =I7+J7+K7+L7 -> 90 | O7: ₱3M+ budget · hands-on operator · F&B owner | P7: 🔥 HOT — Call Today | Q7: Call within 24hr; pitch full deck
A8: 7 | B8: Sofia Kamille Tagle | C8: +639686500117 | D8: sofiakamille888@gmail.com | E8: 2026-04-25 03:49 | F8: Investor | G8: Both (operator + investor) | H8: ₱3,000,000+ | I8: 12 | J8: 30 | K8: 40 | L8: 5 | N8: =I8+J8+K8+L8 -> 87 | O8: ₱3M+ budget · wants both roles · investor profile | P8: 🔥 HOT — Call Today | Q8: Call within 24hr; pitch full deck
A9: 8 | B9: Millie de Luna-Daluz | C9: +639178650824 | D9: millie@aluyan.ph | E9: 2026-04-25 06:02 | F9: Business owner (Non-F&B) | G9: Active operator (hands-on) | H9: ₱3,000,000+ | I9: 15 | J9: 25 | K9: 40 | L9: 5 | N9: =I9+J9+K9+L9 -> 85 | O9: ₱3M+ budget · hands-on operator · non-F&B owner | P9: 🔥 HOT — Call Today | Q9: Call within 24hr; pitch full deck
A10: 9 | B10: Mark Lopez | C10: +639178776275 | D10: lopezmarkkelvin@gmail.com | E10: 2026-04-26 15:05 | F10: Business owner (F&B) | G10: Both (operator + investor) | H10: ₱1,000,000 – ₱3,000,000 | I10: 20 | J10: 30 | K10: 25 | L10: 5 | N10: =I10+J10+K10+L10 -> 80 | O10: ₱1-3M budget · wants both roles · F&B owner | P10: 🔥 HOT — Call Today | Q10: Call within 24hr; pitch full deck
A11: 10 | B11: Tish Darroca | C11: +639778069760 | D11: darroca.patricia@gmail.com | E11: 2026-04-25 12:57 | F11: Business owner (F&B) | G11: Both (operator + investor) | H11: ₱1,000,000 – ₱3,000,000 | I11: 20 | J11: 30 | K11: 25 | L11: 5 | N11: =I11+J11+K11+L11 -> 80 | O11: ₱1-3M budget · wants both roles · F&B owner | P11: 🔥 HOT — Call Today | Q11: Call within 24hr; pitch full deck
A12: 11 | B12: Charles Lee | C12: +639155304159 | D12: charles.james.lee99@gmail.com | E12: 2026-04-24 13:13 | F12: Business owner (F&B) | G12: Both (operator + investor) | H12: ₱1,000,000 – ₱3,000,000 | I12: 20 | J12: 30 | K12: 25 | L12: 5 | N12: =I12+J12+K12+L12 -> 80 | O12: ₱1-3M budget · wants both roles · F&B owner | P12: 🔥 HOT — Call Today | Q12: Call within 24hr; pitch full deck
A13: 12 | B13: Clare Alvarez | C13: +639175988269 | D13: clare.alvarez@guildsec.com | E13: 2026-04-28 12:11 | F13: Business owner (F&B) | G13: Active operator (hands-on) | H13: ₱1,000,000 – ₱3,000,000 | I13: 20 | J13: 25 | K13: 25 | L13: 5 | N13: =I13+J13+K13+L13 -> 75 | O13: ₱1-3M budget · hands-on operator · F&B owner | P13: ⭐ Warm — Call This Week | Q13: Call this week; qualify investment timeline
A14: 13 | B14: Sheery He | C14: +639177188658 | D14: sheeryhe.ogci@yahoo.com | E14: 2026-04-25 00:46 | F14: Business owner (Non-F&B) | G14: Both (operator + investor) | H14: ₱1,000,000 – ₱3,000,000 | I14: 15 | J14: 30 | K14: 25 | L14: 5 | N14: =I14+J14+K14+L14 -> 75 | O14: ₱1-3M budget · wants both roles · non-F&B owner | P14: ⭐ Warm — Call This Week | Q14: Call this week; qualify investment timeline
A15: 14 | B15: Patricia Darroca | C15: +639778069760 | D15: darroca.patricia@gmail.com | E15: 2026-04-23 17:25 | F15: Business owner (Non-F&B) | G15: Both (operator + investor) | H15: ₱1,000,000 – ₱3,000,000 | I15: 15 | J15: 30 | K15: 25 | L15: 5 | N15: =I15+J15+K15+L15 -> 75 | O15: ₱1-3M budget · wants both roles · non-F&B owner | P15: ⭐ Warm — Call This Week | Q15: Call this week; qualify investment timeline
A16: 15 | B16: RV Navia | D16: unessima@gmail.com | E16: 2026-04-23 15:27 | F16: Investor | G16: Both (operator + investor) | H16: ₱1,000,000 – ₱3,000,000 | I16: 12 | J16: 30 | K16: 25 | L16: 5 | N16: =I16+J16+K16+L16 -> 72 | O16: ₱1-3M budget · wants both roles · investor profile | P16: ⭐ Warm — Call This Week | Q16: Call this week; qualify investment timeline
A17: 16 | B17: arah jae | C17: +639171921127 | D17: arahjaemarcelo@gmail.com | E17: 2026-04-29 03:24 | F17: Investor | G17: Active operator (hands-on) | H17: ₱1,000,000 – ₱3,000,000 | I17: 12 | J17: 25 | K17: 25 | L17: 5 | N17: =I17+J17+K17+L17 -> 67 | O17: ₱1-3M budget · hands-on operator · investor profile | P17: ⭐ Warm — Call This Week | Q17: Call this week; qualify investment timeline
A18: 17 | B18: Dianne Abella | C18: +639178331491 | D18: dianne.abella@gmail.com | E18: 2026-04-29 02:44 | F18: Planning to start a business | G18: Both (operator + investor) | H18: ₱1,000,000 – ₱3,000,000 | I18: 5 | J18: 30 | K18: 25 | L18: 5 | N18: =I18+J18+K18+L18 -> 65 | O18: ₱1-3M budget · wants both roles · first-time founder | P18: ⭐ Warm — Call This Week | Q18: Call this week; qualify investment timeline
A19: 18 | B19: RJ Villegas | C19: +639175830209 | D19: rjsjvillegas@gmail.com | E19: 2026-04-28 16:12 | F19: Business owner (Non-F&B) | G19: Investor (capital only) | H19: ₱1,000,000 – ₱3,000,000 | I19: 15 | J19: 20 | K19: 25 | L19: 5 | N19: =I19+J19+K19+L19 -> 65 | O19: ₱1-3M budget · capital-only investor · non-F&B owner | P19: ⭐ Warm — Call This Week | Q19: Call this week; qualify investment timeline
A20: 19 | B20: Mariel Gamboa | C20: +639171231235 | D20: marielgamboa131@gmail.com | E20: 2026-04-27 07:02 | F20: Planning to start a business | G20: Both (operator + investor) | H20: ₱1,000,000 – ₱3,000,000 | I20: 5 | J20: 30 | K20: 25 | L20: 5 | N20: =I20+J20+K20+L20 -> 65 | O20: ₱1-3M budget · wants both roles · first-time founder | P20: ⭐ Warm — Call This Week | Q20: Call this week; qualify investment timeline
A21: 20 | B21: Kel Pascual | C21: +639175150889 | D21: kelpascual100@gmail.com | E21: 2026-04-27 03:11 | F21: Business owner (F&B) | G21: Both (operator + investor) | H21: ₱500,000 – ₱1,000,000 | I21: 20 | J21: 30 | K21: 10 | L21: 5 | N21: =I21+J21+K21+L21 -> 65 | O21: ₱500K-1M budget · wants both roles · F&B owner | P21: ⭐ Warm — Call This Week | Q21: Call this week; qualify investment timeline
A22: 21 | B22: Vince Klein | C22: 017673042970 | D22: Kvgio@icloud.com | E22: 2026-04-26 20:41 | F22: Business owner (F&B) | G22: Both (operator + investor) | H22: ₱500,000 – ₱1,000,000 | I22: 20 | J22: 30 | K22: 10 | L22: 5 | N22: =I22+J22+K22+L22 -> 65 | O22: ₱500K-1M budget · wants both roles · F&B owner | P22: ⭐ Warm — Call This Week | Q22: Call this week; qualify investment timeline
A23: 22 | B23: Erick | C23: +639176338553 | D23: erick.dl815@gmail.com | E23: 2026-04-26 20:33 | F23: Business owner (F&B) | G23: Both (operator + investor) | H23: ₱500,000 – ₱1,000,000 | I23: 20 | J23: 30 | K23: 10 | L23: 5 | N23: =I23+J23+K23+L23 -> 65 | O23: ₱500K-1M budget · wants both roles · F&B owner | P23: ⭐ Warm — Call This Week | Q23: Call this week; qualify investment timeline
A24: 23 | B24: Nicole Alba | C24: +639760194972 | D24: alba.nicoleee@gmail.com | E24: 2026-04-26 11:28 | F24: Planning to start a business | G24: Both (operator + investor) | H24: ₱1,000,000 – ₱3,000,000 | I24: 5 | J24: 30 | K24: 25 | L24: 5 | N24: =I24+J24+K24+L24 -> 65 | O24: ₱1-3M budget · wants both roles · first-time founder | P24: ⭐ Warm — Call This Week | Q24: Call this week; qualify investment timeline
A25: 24 | B25: David Mirasol | C25: 639052946188 | D25: david.mirasol01@gmail.com | E25: 2026-04-25 14:46 | F25: Planning to start a business | G25: Both (operator + investor) | H25: ₱1,000,000 – ₱3,000,000 | I25: 5 | J25: 30 | K25: 25 | L25: 5 | N25: =I25+J25+K25+L25 -> 65 | O25: ₱1-3M budget · wants both roles · first-time founder | P25: ⭐ Warm — Call This Week | Q25: Call this week; qualify investment timeline
A26: 25 | B26: Mark Acosta | C26: +639176236632 | D26: markangelo_acosta@yahoo.com | E26: 2026-04-25 14:15 | F26: Planning to start a business | G26: Both (operator + investor) | H26: ₱1,000,000 – ₱3,000,000 | I26: 5 | J26: 30 | K26: 25 | L26: 5 | N26: =I26+J26+K26+L26 -> 65 | O26: ₱1-3M budget · wants both roles · first-time founder | P26: ⭐ Warm — Call This Week | Q26: Call this week; qualify investment timeline
A27: 26 | B27: Veronika Asis | C27: +17253039650 | D27: vronimain@gmail.com | E27: 2026-04-24 02:27 | F27: Business owner (F&B) | G27: Both (operator + investor) | H27: ₱500,000 – ₱1,000,000 | I27: 20 | J27: 30 | K27: 10 | L27: 5 | N27: =I27+J27+K27+L27 -> 65 | O27: ₱500K-1M budget · wants both roles · F&B owner | P27: ⭐ Warm — Call This Week | Q27: Call this week; qualify investment timeline
A28: 27 | B28: Therese del Rosario | C28: +639064454370 | D28: theresedelrosario13@gmail.com | E28: 2026-04-23 13:24 | F28: Planning to start a business | G28: Both (operator + investor) | H28: ₱1,000,000 – ₱3,000,000 | I28: 5 | J28: 30 | K28: 25 | L28: 5 | N28: =I28+J28+K28+L28 -> 65 | O28: ₱1-3M budget · wants both roles · first-time founder | P28: ⭐ Warm — Call This Week | Q28: Call this week; qualify investment timeline
A29: 28 | B29: Paula Mae Roldan | D29: paulamaeyambaoroldan@gmail.com | E29: 2026-04-23 12:36 | F29: Business owner (F&B) | G29: Both (operator + investor) | H29: ₱500,000 – ₱1,000,000 | I29: 20 | J29: 30 | K29: 10 | L29: 5 | N29: =I29+J29+K29+L29 -> 65 | O29: ₱500K-1M budget · wants both roles · F&B owner | P29: ⭐ Warm — Call This Week | Q29: Call this week; qualify investment timeline
A30: 29 | B30: Kimber Diaz Cesa | C30: +639174938493 | D30: kimberdiazcesa@gmail.com | E30: 2026-04-23 12:01 | F30: Planning to start a business | G30: Both (operator + investor) | H30: ₱1,000,000 – ₱3,000,000 | I30: 5 | J30: 30 | K30: 25 | L30: 5 | N30: =I30+J30+K30+L30 -> 65 | O30: ₱1-3M budget · wants both roles · first-time founder | P30: ⭐ Warm — Call This Week | Q30: Call this week; qualify investment timeline
A31: 30 | B31: Tim Marcelo | C31: +639173094945 | D31: Sylveropc@gmail.com | E31: 2026-04-23 11:32 | F31: Business owner (F&B) | G31: Both (operator + investor) | H31: ₱500,000 – ₱1,000,000 | I31: 20 | J31: 30 | K31: 10 | L31: 5 | N31: =I31+J31+K31+L31 -> 65 | O31: ₱500K-1M budget · wants both roles · F&B owner | P31: ⭐ Warm — Call This Week | Q31: Call this week; qualify investment timeline
A32: 31 | B32: Aaron Dela Cruz | C32: +63639681772 | D32: aaronddc@yahoo.com | E32: 2026-04-23 11:09 | F32: Business owner (F&B) | G32: Both (operator + investor) | H32: ₱500,000 – ₱1,000,000 | I32: 20 | J32: 30 | K32: 10 | L32: 3 | N32: =I32+J32+K32+L32 -> 63 | O32: ₱500K-1M budget · wants both roles · F&B owner | P32: ⭐ Warm — Call This Week | Q32: Call this week; qualify investment timeline
A33: 32 | B33: Bruce Wang | C33: +639776777898 | D33: brucewangback@gmail.com | E33: 2026-04-26 22:58 | F33: Investor | G33: Investor (capital only) | H33: ₱1,000,000 – ₱3,000,000 | I33: 12 | J33: 20 | K33: 25 | L33: 5 | N33: =I33+J33+K33+L33 -> 62 | O33: ₱1-3M budget · capital-only investor · investor profile | P33: ⭐ Warm — Call This Week | Q33: Call this week; qualify investment timeline
A34: 33 | B34: Gigi A. santos | C34: +639272551548 | D34: angelisasantos@yahoo.com | E34: 2026-04-29 13:26 | F34: Business owner (Non-F&B) | G34: Both (operator + investor) | H34: ₱500,000 – ₱1,000,000 | I34: 15 | J34: 30 | K34: 10 | L34: 5 | N34: =I34+J34+K34+L34 -> 60 | O34: ₱500K-1M budget · wants both roles · non-F&B owner | P34: ⭐ Warm — Call This Week | Q34: Call this week; qualify investment timeline
A35: 34 | B35: Rainier mozo | C35: +639178654545 | D35: rainiermozomd@yahoo.com | E35: 2026-04-29 03:39 | F35: Business owner (Non-F&B) | G35: Both (operator + investor) | H35: ₱500,000 – ₱1,000,000 | I35: 15 | J35: 30 | K35: 10 | L35: 5 | N35: =I35+J35+K35+L35 -> 60 | O35: ₱500K-1M budget · wants both roles · non-F&B owner | P35: ⭐ Warm — Call This Week | Q35: Call this week; qualify investment timeline
A36: 35 | B36: Jyle Go Chuahiock | C36: +639175010022 | D36: gojyle@gmail.com | E36: 2026-04-28 02:34 | F36: Business owner (F&B) | G36: Active operator (hands-on) | H36: ₱500,000 – ₱1,000,000 | I36: 20 | J36: 25 | K36: 10 | L36: 5 | N36: =I36+J36+K36+L36 -> 60 | O36: ₱500K-1M budget · hands-on operator · F&B owner | P36: ⭐ Warm — Call This Week | Q36: Call this week; qualify investment timeline
A37: 36 | B37: Pamela Licup | C37: 09175601868 | D37: Pamrosse.8888@gmail.com | E37: 2026-04-27 04:29 | F37: Business owner (Non-F&B) | G37: Both (operator + investor) | H37: ₱500,000 – ₱1,000,000 | I37: 15 | J37: 30 | K37: 10 | L37: 5 | N37: =I37+J37+K37+L37 -> 60 | O37: ₱500K-1M budget · wants both roles · non-F&B owner | P37: ⭐ Warm — Call This Week | Q37: Call this week; qualify investment timeline
A38: 37 | B38: Chingky Fuentes Sto Tomas | C38: +639178862867 | D38: vineranza01@gmail.com | E38: 2026-04-26 15:19 | F38: Business owner (Non-F&B) | G38: Both (operator + investor) | H38: ₱500,000 – ₱1,000,000 | I38: 15 | J38: 30 | K38: 10 | L38: 5 | N38: =I38+J38+K38+L38 -> 60 | O38: ₱500K-1M budget · wants both roles · non-F&B owner | P38: ⭐ Warm — Call This Week | Q38: Call this week; qualify investment timeline
A39: 38 | B39: Kristen Tan | C39: +639178415646 | D39: kcstan@gqwest.com | E39: 2026-04-26 11:05 | F39: Business owner (Non-F&B) | G39: Both (operator + investor) | H39: ₱500,000 – ₱1,000,000 | I39: 15 | J39: 30 | K39: 10 | L39: 5 | N39: =I39+J39+K39+L39 -> 60 | O39: ₱500K-1M budget · wants both roles · non-F&B owner | P39: ⭐ Warm — Call This Week | Q39: Call this week; qualify investment timeline
A40: 39 | B40: Christian Samonte | C40: +639064376309 | D40: box.christianjs@gmail.com | E40: 2026-04-25 21:03 | F40: Business owner (Non-F&B) | G40: Both (operator + investor) | H40: ₱500,000 – ₱1,000,000 | I40: 15 | J40: 30 | K40: 10 | L40: 5 | N40: =I40+J40+K40+L40 -> 60 | O40: ₱500K-1M budget · wants both roles · non-F&B owner | P40: ⭐ Warm — Call This Week | Q40: Call this week; qualify investment timeline
...

Sheet Scoring Logic
A1: How leads are scored
A2: Designed for urgency: serious + aligned + fast money release. Edit point values here to re-rank.
A4: 💰 Investment Range (max 40 pts) — biggest weight: ability to release capital fast
A5: Bucket | B5: Points / Threshold
A6: ₱3,000,000+ | B6: 40
A7: ₱1,000,000 – ₱3,000,000 | B7: 25
A8: ₱500,000 – ₱1,000,000 | B8: 10
A10: 🤝 Involvement Type (max 30 pts) — operator-investors close fastest
A11: Bucket | B11: Points / Threshold
A12: Both (operator + investor) | B12: 30
A13: Active operator (hands-on) | B13: 25
A14: Investor (capital only) | B14: 20
A16: 👤 Profile Fit (max 20 pts) — F&B owners need least education
A17: Bucket | B17: Points / Threshold
A18: Business owner (F&B) | B18: 20
A19: Business owner (Non-F&B) | B19: 15
A20: Investor | B20: 12
A21: Planning to start | B21: 5
A23: ⏱️ Recency (max 10 pts) — fresh leads convert better
A24: Bucket | B24: Points / Threshold
A25: Last 3 days | B25: 10
A26: Last 7 days | B26: 7
A27: Last 14 days | B27: 5
A28: Older | B28: 3
A30: 🏷️ Priority Tiers
A31: Bucket | B31: Points / Threshold
A32: 🔥 HOT — Call Today | B32: ≥ 80
A33: ⭐ Warm — Call This Week | B33: 60 – 79
A34: 📋 Qualified — Email First | B34: 40 – 59
A35: ❄️ Low — Nurture | B35: < 40

Sheet Raw Data
A1: id | B1: created_time | C1: ad_id | D1: ad_name | E1: adset_id | F1: adset_name | G1: campaign_id | H1: campaign_name | I1: form_id | J1: form_name | K1: is_organic | L1: platform | M1: what_best_describes_you? | N1: what_is_your_level_of_involvement_for_this_opportunity? | O1: what_is_your_estimated_investment_range? | P1: email | Q1: full_name | R1: phone | S1: lead_status
A2: l:1892255954812753 | B2: 2026-04-21T06:09:25-05:00 | I2: f:1702622264247163 | J2: MOA Partner Application | K2: True | M2: <test lead: dummy data for what_best_describes_you?> | N2: <test lead: dummy data for what_is_your_level_of_involvement_for_this_opportunity?> | O2: <test lead: dummy data for what_is_your_estimated_investment_range?> | P2: test@meta.com | Q2: <test lead: dummy data for full_name> | R2: p:<test lead: dummy data for phone> | S2: CONTACTED
A3: l:990896806942192 | B3: 2026-04-23T03:43:05-05:00 | C3: ag:120242606318310575 | D3: Image Ad | MOA Flagship Partner | E3: as:120242606318320575 | F3: Cold | Entrepreneurs (SMB/Startup) | G3: c:120242539768020575 | H3: MOA Partner Opportunity | Leads | I3: f:1702622264247163 | J3: MOA Partner Application | K3: False | L3: fb | M3: business_owner_(f&b) | N3: investor_(capital_only) | O3: ₱500,000_–_₱1,000,000 | P3: christineeunicedy@gmail.com | Q3: Christine Dy-Chua | R3: p:+639172513332 | S3: CREATED
A4: l:1721673092527397 | B4: 2026-04-23T04:28:15-05:00 | C4: ag:120242606318310575 | D4: Image Ad | MOA Flagship Partner | E4: as:120242606318320575 | F4: Cold | Entrepreneurs (SMB/Startup) | G4: c:120242539768020575 | H4: MOA Partner Opportunity | Leads | I4: f:1702622264247163 | J4: MOA Partner Application | K4: False | L4: fb | M4: business_owner_(f&b) | N4: investor_(capital_only) | O4: ₱500,000_–_₱1,000,000 | P4: lanzthedog@gmail.com | Q4: Lanz castillo | R4: p:+639175524333 | S4: CREATED
A5: l:1705358400477101 | B5: 2026-04-23T04:30:52-05:00 | C5: ag:120242539768010575 | D5: Image Ad | MOA Flagship Partner | E5: as:120242539768220575 | F5: Cold | F&B Owners (Cafe/Restaurant) | G5: c:120242539768020575 | H5: MOA Partner Opportunity | Leads | I5: f:1702622264247163 | J5: MOA Partner Application | K5: False | L5: ig | M5: investor | N5: investor_(capital_only) | O5: ₱500,000_–_₱1,000,000 | P5: backpackerph155@gmail.com | Q5: Emman | R5: p:09162732212 | S5: CREATED
A6: l:2032687467315097 | B6: 2026-04-23T05:01:48-05:00 | C6: ag:120242606318310575 | D6: Image Ad | MOA Flagship Partner | E6: as:120242606318320575 | F6: Cold | Entrepreneurs (SMB/Startup) | G6: c:120242539768020575 | H6: MOA Partner Opportunity | Leads | I6: f:1702622264247163 | J6: MOA Partner Application | K6: False | L6: fb | M6: investor | N6: investor_(capital_only) | O6: ₱500,000_–_₱1,000,000 | P6: joshhgellido@yahoo.com | Q6: Joshua Gellido | R6: p:+639175037130 | S6: CREATED
A7: l:1465519458400108 | B7: 2026-04-23T06:09:03-05:00 | C7: ag:120242539768010575 | D7: Image Ad | MOA Flagship Partner | E7: as:120242539768220575 | F7: Cold | F&B Owners (Cafe/Restaurant) | G7: c:120242539768020575 | H7: MOA Partner Opportunity | Leads | I7: f:1702622264247163 | J7: MOA Partner Application | K7: False | L7: fb | M7: business_owner_(f&b) | N7: both_(operator_+_investor) | O7: ₱500,000_–_₱1,000,000 | P7: aaronddc@yahoo.com | Q7: Aaron Dela Cruz | R7: p:+63639681772 | S7: CREATED
A8: l:2092542861594648 | B8: 2026-04-23T06:32:59-05:00 | C8: ag:120242606318300575 | D8: Image Ad | MOA Flagship Partner | E8: as:120242606318290575 | F8: Cold | Investors (Angel/Capital) | G8: c:120242539768020575 | H8: MOA Partner Opportunity | Leads | I8: f:1702622264247163 | J8: MOA Partner Application | K8: False | L8: fb | M8: business_owner_(f&b) | N8: both_(operator_+_investor) | O8: ₱500,000_–_₱1,000,000 | P8: Sylveropc@gmail.com | Q8: Tim Marcelo | R8: p:+639173094945 | S8: CREATED
A9: l:949346297806547 | B9: 2026-04-23T06:45:06-05:00 | C9: ag:120242606318310575 | D9: Image Ad | MOA Flagship Partner | E9: as:120242606318320575 | F9: Cold | Entrepreneurs (SMB/Startup) | G9: c:120242539768020575 | H9: MOA Partner Opportunity | Leads | I9: f:1702622264247163 | J9: MOA Partner Application | K9: False | L9: ig | M9: investor | N9: both_(operator_+_investor) | O9: ₱500,000_–_₱1,000,000 | P9: rmgrabino@yahoo.com.ph | Q9: Rachelle Rabino Corpuz | R9: p:+639294905486 | S9: CREATED
A10: l:26581650814790765 | B10: 2026-04-23T07:01:05-05:00 | C10: ag:120242606318300575 | D10: Image Ad | MOA Flagship Partner | E10: as:120242606318290575 | F10: Cold | Investors (Angel/Capital) | G10: c:120242539768020575 | H10: MOA Partner Opportunity | Leads | I10: f:1702622264247163 | J10: MOA Partner Application | K10: False | L10: ig | M10: planning_to_start_a_business | N10: both_(operator_+_investor) | O10: ₱1,000,000_–_₱3,000,000 | P10: kimberdiazcesa@gmail.com | Q10: Kimber Diaz Cesa | R10: p:+639174938493 | S10: CREATED
A11: l:2775420789487825 | B11: 2026-04-23T07:01:54-05:00 | C11: ag:120242606318300575 | D11: Image Ad | MOA Flagship Partner | E11: as:120242606318290575 | F11: Cold | Investors (Angel/Capital) | G11: c:120242539768020575 | H11: MOA Partner Opportunity | Leads | I11: f:1702622264247163 | J11: MOA Partner Application | K11: False | L11: fb | M11: business_owner_(non-f&b) | N11: active_operator_(hands-on) | O11: ₱500,000_–_₱1,000,000 | P11: veniceachurra@yahoo.com | Q11: Venice Barrios | R11: p:+639563375538 | S11: CREATED
A12: l:1451191642823430 | B12: 2026-04-23T07:15:01-05:00 | C12: ag:120242606318310575 | D12: Image Ad | MOA Flagship Partner | E12: as:120242606318320575 | F12: Cold | Entrepreneurs (SMB/Startup) | G12: c:120242539768020575 | H12: MOA Partner Opportunity | Leads | I12: f:1702622264247163 | J12: MOA Partner Application | K12: False | L12: fb | M12: planning_to_start_a_business | N12: both_(operator_+_investor) | O12: ₱500,000_–_₱1,000,000 | P12: justinesepherene@gmail.com | Q12: Justine Nicole Borbe | R12: p:+639398461039 | S12: CREATED
A13: l:1864451757578038 | B13: 2026-04-23T07:31:46-05:00 | C13: ag:120242606318310575 | D13: Image Ad | MOA Flagship Partner | E13: as:120242606318320575 | F13: Cold | Entrepreneurs (SMB/Startup) | G13: c:120242539768020575 | H13: MOA Partner Opportunity | Leads | I13: f:1702622264247163 | J13: MOA Partner Application | K13: False | L13: ig | M13: investor | N13: both_(operator_+_investor) | O13: ₱500,000_–_₱1,000,000 | P13: villarsteffi@gmail.com | Q13: Steffi Villar | R13: p:+639174799888 | S13: CREATED
A14: l:1546890133765970 | B14: 2026-04-23T07:36:41-05:00 | C14: ag:120242606318310575 | D14: Image Ad | MOA Flagship Partner | E14: as:120242606318320575 | F14: Cold | Entrepreneurs (SMB/Startup) | G14: c:120242539768020575 | H14: MOA Partner Opportunity | Leads | I14: f:1702622264247163 | J14: MOA Partner Application | K14: False | L14: fb | M14: business_owner_(f&b) | N14: both_(operator_+_investor) | O14: ₱500,000_–_₱1,000,000 | P14: paulamaeyambaoroldan@gmail.com | Q14: Paula Mae Roldan | R14: p: | S14: CREATED
... A123: l:1310215231009259 | B123: 2026-04-29T08:26:02-05:00 | C123: ag:120242539768010575 | D123: Image Ad | MOA Flagship Partner | E123: as:120242539768220575 | F123: Cold | F&B Owners (Cafe/Restaurant) | G123: c:120242539768020575 | H123: MOA Partner Opportunity | Leads | I123: f:1702622264247163 | J123: MOA Partner Application | K123: False | L123: ig | M123: business_owner_(non-f&b) | N123: both_(operator_+_investor) | O123: ₱500,000_–_₱1,000,000 | P123: angelisasantos@yahoo.com | Q123: Gigi A. santos | R123: p:+639272551548 | S123: CREATED
